Workbook

Sheet Sheet1
A1: Kode Tk* | B1: KPJ* | C1: Nomor Identitas* | D1: Nama Lengkap | E1: Tempat Lahir | F1: Tanggal Lahir | G1: Telp Area Rumah | H1: Telp Rumah | I1: Telp Area Kantor | J1: Telp Kantor | K1: Telp Ext Kantor | L1: Fax Area | M1: Fax | N1: Email | O1: Handphone | P1: Valid Handphone | Q1: Alamat Domisili | R1: Surat Menyurat Ke | S1: Lokasi Pekerjaan | T1: NPWP | U1: PKWT | V1: Tanggal Awal Bekerja | W1: Tanggal Akhir Kontrak | X1: Nama Ibu Kandung | Y1: Kode Bank | Z1: Nama Bank | AA1: No Rekening | AB1: Nama Rekening | AC1: IBU | AD1: NO HP | AE1: EMAIL
A2: 900000186073893 | B2: 26068950158 | C2: 3515063012030001 | D2: BIMA SYAFA FIRDAUS | E2: SIDOARJO | F2: 30-12-2003 | N2: SYAFAFIRDAUS91@GMAIL.COM | O2: 6281216401466 | P2: T | Q2: RT 0/ RW 0 2014 7 3515 KODE POS 0 | R2: S | S2: 3515 | T2: 0 | U2: Y | V2: 01-04-2026 | W2: 31-12-2026 | X2: HINDUN ALKURIYAH | AC2: =VLOOKUP(B2,Sheet2!$D$2:$L$1283,9,0) -> HINDUN ALKURIYAH | AD2: =VLOOKUP(B2,Sheet2!$D$2:$N$1283,10,0) -> 6281216401466 | AE2: =VLOOKUP(B2,Sheet2!$D$2:$N$1283,11,0) -> SYAFAFIRDAUS91@GMAIL.COM
A3: 900000186073896 | B3: 26068950182 | C3: 3217020208010003 | D3: IKSAN SOFIAN | E3: BANDUNG | F3: 02-08-2001 | N3: IKHSANSOFYAN31@GMAIL.COM | O3: 6281572521216 | P3: T | Q3: RT 0/ RW 0 2004 2 3204 KODE POS 0 | R3: S | S3: 3515 | T3: 0 | U3: Y | V3: 01-04-2026 | W3: 31-12-2026 | X3: SITI SOFIAH | AC3: =VLOOKUP(B3,Sheet2!$D$2:$L$1283,9,0) -> SITI SOFIAH | AD3: =VLOOKUP(B3,Sheet2!$D$2:$N$1283,10,0) -> 6281572521216 | AE3: =VLOOKUP(B3,Sheet2!$D$2:$N$1283,11,0) -> IKHSANSOFYAN31@GMAIL.COM
A4: 105003363 | B4: 11031367813 | C4: 3578166508930006 | D4: UMI HANIK AMALIA | E4: SURABAYA | F4: 25-08-1993 | N4: UMMY.HANNY25@GMAIL.COM | O4: 082244489330 | P4: T | Q4: JL.BULAK BANTENG WETAN IXNO.2 SURABAYA | R4: S | T4: 0 | U4: Y | V4: 01-04-2026 | W4: 31-12-2026 | X4: HUSNIA | AC4: =VLOOKUP(B4,Sheet2!$D$2:$L$1283,9,0) -> #N/A | AD4: =VLOOKUP(B4,Sheet2!$D$2:$N$1283,10,0) -> #N/A | AE4: =VLOOKUP(B4,Sheet2!$D$2:$N$1283,11,0) -> #N/A
AC5: =VLOOKUP(B5,Sheet2!$D$2:$L$1283,9,0) -> #N/A | AD5: =VLOOKUP(B5,Sheet2!$D$2:$N$1283,10,0) -> #N/A | AE5: =VLOOKUP(B5,Sheet2!$D$2:$N$1283,11,0) -> #N/A
AC6: =VLOOKUP(B6,Sheet2!$D$2:$L$1283,9,0) -> #N/A | AD6: =VLOOKUP(B6,Sheet2!$D$2:$N$1283,10,0) -> #N/A | AE6: =VLOOKUP(B6,Sheet2!$D$2:$N$1283,11,0) -> #N/A
AC7: =VLOOKUP(B7,Sheet2!$D$2:$L$1283,9,0) -> #N/A | AD7: =VLOOKUP(B7,Sheet2!$D$2:$N$1283,10,0) -> #N/A | AE7: =VLOOKUP(B7,Sheet2!$D$2:$N$1283,11,0) -> #N/A
AC8: =VLOOKUP(B8,Sheet2!$D$2:$L$1283,9,0) -> #N/A | AD8: =VLOOKUP(B8,Sheet2!$D$2:$N$1283,10,0) -> #N/A | AE8: =VLOOKUP(B8,Sheet2!$D$2:$N$1283,11,0) -> #N/A
AC9: =VLOOKUP(B9,Sheet2!$D$2:$L$1283,9,0) -> #N/A | AD9: =VLOOKUP(B9,Sheet2!$D$2:$N$1283,10,0) -> #N/A | AE9: =VLOOKUP(B9,Sheet2!$D$2:$N$1283,11,0) -> #N/A
AC10: =VLOOKUP(B10,Sheet2!$D$2:$L$1283,9,0) -> #N/A | AD10: =VLOOKUP(B10,Sheet2!$D$2:$N$1283,10,0) -> #N/A | AE10: =VLOOKUP(B10,Sheet2!$D$2:$N$1283,11,0) -> #N/A
AC11: =VLOOKUP(B11,Sheet2!$D$2:$L$1283,9,0) -> #N/A | AD11: =VLOOKUP(B11,Sheet2!$D$2:$N$1283,10,0) -> #N/A | AE11: =VLOOKUP(B11,Sheet2!$D$2:$N$1283,11,0) -> #N/A
AC12: =VLOOKUP(B12,Sheet2!$D$2:$L$1283,9,0) -> #N/A | AD12: =VLOOKUP(B12,Sheet2!$D$2:$N$1283,10,0) -> #N/A | AE12: =VLOOKUP(B12,Sheet2!$D$2:$N$1283,11,0) -> #N/A
AC13: =VLOOKUP(B13,Sheet2!$D$2:$L$1283,9,0) -> #N/A | AD13: =VLOOKUP(B13,Sheet2!$D$2:$N$1283,10,0) -> #N/A | AE13: =VLOOKUP(B13,Sheet2!$D$2:$N$1283,11,0) -> #N/A
AC14: =VLOOKUP(B14,Sheet2!$D$2:$L$1283,9,0) -> #N/A | AD14: =VLOOKUP(B14,Sheet2!$D$2:$N$1283,10,0) -> #N/A | AE14: =VLOOKUP(B14,Sheet2!$D$2:$N$1283,11,0) -> #N/A
AC15: =VLOOKUP(B15,Sheet2!$D$2:$L$1283,9,0) -> #N/A | AD15: =VLOOKUP(B15,Sheet2!$D$2:$N$1283,10,0) -> #N/A | AE15: =VLOOKUP(B15,Sheet2!$D$2:$N$1283,11,0) -> #N/A
AC16: =VLOOKUP(B16,Sheet2!$D$2:$L$1283,9,0) -> #N/A | AD16: =VLOOKUP(B16,Sheet2!$D$2:$N$1283,10,0) -> #N/A | AE16: =VLOOKUP(B16,Sheet2!$D$2:$N$1283,11,0) -> #N/A
... AC1402: =VLOOKUP(B1402,Sheet2!$D$2:$L$1283,9,0) -> #N/A | AD1402: =VLOOKUP(B1402,Sheet2!$D$2:$N$1283,10,0) -> #N/A | AE1402: =VLOOKUP(B1402,Sheet2!$D$2:$N$1283,11,0) -> #N/A

Sheet Sheet3
A1: 900000188076812 | B1: 26068390579 | C1: 3515186102060003 | D1: MARISANA MILATAL KHAQ | E1: SIDOARJO | F1: 21-02-2006 | N1: MARISSANAICA@GMAIL.COM | O1: 6281231469851 | P1: T | Q1: RT 0/ RW 0 2011 18 3515 KODE POS 0 | R1: S | T1: 0 | U1: T | V1: 01-05-2026 | W1: 31-12-3000 | X1: RIYANI FITRIA R | AC1: RIYANI FITRIA R | AD1: 6281231469851 | AE1: MARISSANAICA@GMAIL.COM
A2: 900000188076815 | B2: 26068390603 | C2: 3515185707800010 | D2: SITI MALIKAH | E2: BOJONEGORO | F2: 17-07-1980 | N2: TSABITNASABILALKHOIR@GMAIL.COM | O2: 6288231812859 | P2: T | Q2: RT 0/ RW 0 2011 18 3515 KODE POS | R2: S | T2: 0 | U2: T | V2: 01-05-2026 | W2: 31-12-3000 | X2: WAIDJEM | AC2: WAIDJEM | AD2: 6288231812859 | AE2: TSABITNASABILALKHOIR@GMAIL.COM
A3: 900000188076820 | B3: 26068390504 | C3: 3515185605040006 | D3: AISYAH NABILATUS SOLIKHA | E3: SIDOARJO | F3: 16-05-2004 | N3: AISYAHNABILATUS996@GMAIL.COM | O3: 6287703384875 | P3: T | Q3: RT 0/ RW 0 2011 18 3515 KODE POS | R3: S | T3: 0 | U3: T | V3: 01-05-2026 | W3: 31-12-3000 | X3: IKA ROMADHONA | AC3: IKA ROMADHONA | AD3: 6287703384875 | AE3: AISYAHNABILATUS996@GMAIL.COM
A4: 900000188076823 | B4: 26068390538 | C4: 3515180112050002 | D4: MUCHAMMAD HILBRAM WAHYU PUTRA | E4: SIDOARJO | F4: 01-12-2005 | N4: MUCHAMMADHILBRAM@GMAIL.COM | O4: 6287757004076 | P4: T | Q4: RT 0/ RW 0 2011 18 3515 KODE POS 0 | R4: S | T4: 0 | U4: T | V4: 01-05-2026 | W4: 31-12-3000 | X4: THOIFAH | AC4: THOIFAH | AD4: 6287757004076 | AE4: MUCHAMMADHILBRAM@GMAIL.COM
A5: 900000188076826 | B5: 26068390561 | C5: 3515186602950001 | D5: CHURIN LUSIANDY ROMADHONA | E5: SIDOARJO | F5: 26-02-1995 | N5: CLROMADHONA26@GMAIL.COM | O5: 6281330705539 | P5: T | Q5: RT 0/ RW 0 2011 18 3515 KODE POS | R5: S | T5: 0 | U5: T | V5: 01-05-2026 | W5: 31-12-3000 | X5: KHUSNUL QULUQ | AC5: KHUSNUL QULUQ | AD5: 6281330705539 | AE5: CLROMADHONA26@GMAIL.COM
A6: 900000188076829 | B6: 26068390637 | C6: 3515185701980004 | D6: LAILATUZZAKIYAH | E6: SIDOARJO | F6: 17-01-1998 | N6: LAILATUZZAKIYAH@GMAIL.COM | O6: 6285730511224 | P6: T | Q6: RT 0/ RW 0 2011 18 3515 KODE POS 0 | R6: S | T6: 0 | U6: T | V6: 01-05-2026 | W6: 31-12-3000 | X6: HJ. NUR FAIZAH | AC6: HJ. NUR FAIZAH | AD6: 6285730511224 | AE6: LAILATUZZAKIYAH@GMAIL.COM
A7: 900000188076843 | B7: 26068391106 | C7: 3515180303050003 | D7: HASBULLOH MAULANA HUSEIN | E7: SIDOARJO | F7: 03-03-2005 | N7: HASMASEN33@GMAIL.COM | O7: 6285331171826 | P7: T | Q7: RT 0/ RW 0 2011 18 3515 KODE POS 0 | R7: S | T7: 0 | U7: T | V7: 01-05-2026 | W7: 31-12-3000 | X7: NURIL JANAH SRI RAHAYU | AC7: NURIL JANAH SRI RAHAYU | AD7: 6285331171826 | AE7: HASMASEN33@GMAIL.COM
A8: 900000188076852 | B8: 26068390801 | C8: 3515182001020006 | D8: MOH LUKMAN KHAKIM | E8: JOMBANG | F8: 20-01-2002 | N8: MLLUKKMAN@GMAIL.COM | O8: 6289616728493 | P8: T | Q8: RT 0/ RW 0 2011 18 3515 KODE POS 0 | R8: S | T8: 0 | U8: T | V8: 01-05-2026 | W8: 31-12-3000 | X8: SITI UMININ | AC8: SITI UMININ | AD8: 6289616728493 | AE8: MLLUKKMAN@GMAIL.COM
A9: 900000188076854 | B9: 26068390827 | C9: 3515180204010002 | D9: MUHAMMAD ARDIANSYAH | E9: SIDOARJO | F9: 02-04-2001 | N9: VERSYID@GMAIL.COM | O9: 6285831725980 | P9: T | Q9: RT 0/ RW 0 2011 18 3515 KODE POS 0 | R9: S | T9: 0 | U9: T | V9: 01-05-2026 | W9: 31-12-3000 | X9: KATMIASIH | AC9: KATMIASIH | AD9: 6285831725980 | AE9: VERSYID@GMAIL.COM
A10: 900000188076861 | B10: 26068390884 | C10: 3515180808940002 | D10: DHIAN MUR SALEK | E10: SURABAYA | F10: 08-08-1994 | N10: SINGGASANAUNYIL@GMAIL.COM | O10: 6282336637374 | P10: T | Q10: RT 0/ RW 0 2011 18 3515 KODE POS 61256 | R10: S | T10: 0 | U10: T | V10: 01-05-2026 | W10: 31-12-3000 | X10: SUPARTI | AC10: SUPARTI | AD10: 6282336637374 | AE10: SINGGASANAUNYIL@GMAIL.COM
A11: 900000188076863 | B11: 26068390900 | C11: 3515180902990002 | D11: MAS AHMAD FAHMI IDRIS | E11: SURABAYA | F11: 09-02-1999 | N11: MASFEHMI@GMAIL.COM | O11: 6281515447943 | P11: T | Q11: RT 0/ RW 0 2011 18 3515 KODE POS 61256 | R11: S | T11: 0 | U11: T | V11: 01-05-2026 | W11: 31-12-3000 | X11: ANIS KHOIROTI | AC11: ANIS KHOIROTI | AD11: 6281515447943 | AE11: MASFEHMI@GMAIL.COM
A12: 900000188076864 | B12: 26068389795 | C12: 3515172304020002 | D12: M IQBAL BASYA'IR | E12: SIDOARJO | F12: 23-04-2002 | N12: IQBALBASYAIR.SYR@GMAIL.COM | O12: 6285836863429 | P12: T | Q12: RT 0/ RW 0 2011 18 3515 KODE POS | R12: S | T12: 0 | U12: T | V12: 01-05-2026 | W12: 31-12-3000 | X12: NUR ABIDAH | AC12: NUR ABIDAH | AD12: 6285836863429 | AE12: 3515172304020002@GMAIL.COM
... A18: 900000188076884 | B18: 26068390991 | C18: 3506244107000025 | D18: DINA PUSPITA TARI | E18: KEDIRI | F18: 30-09-2005 | N18: DINAPUSPITATARITARI@GMAIL.COM | O18: 6281234211795 | P18: T | Q18: RT 0/ RW 0 2003 24 3515 KODE POS | R18: S | T18: 0 | U18: T | V18: 01-05-2026 | W18: 31-12-3000 | X18: SUSANTI | AC18: SUSANTI | AD18: 6281234211795 | AE18: DINAPUSPITATARITARI@GMAIL.COM
A19: 900000188076889 | B19: 26068390082 | C19: 3515187005050010 | D19: DENATA AMELIA ZAHARA | E19: SIDOARJO | F19: 30-05-2005 | N19: DENATAAMELIAZ@GMAIL.COM | O19: 6283830008391 | P19: T | Q19: RT 0/ RW 0 3515 KODE POS | R19: S | T19: 0 | U19: T | V19: 01-05-2026 | W19: 31-12-3000 | X19: RINA LELIANA | AC19: RINA LELIANA
A20: 900000188076904 | B20: 26068390363 | C20: 3515182811880009 | D20: PRIYA NOVA SEMBADA | E20: NGANJUK | F20: 28-11-1988 | N20: CB.ARBY22@GMAIL.COM | O20: 6285731200396 | P20: T | Q20: RT 0/ RW 0 2011 18 3515 KODE POS 61256 | R20: S | T20: 0 | U20: T | V20: 01-05-2026 | W20: 31-12-3000 | X20: SUPRIATI | AC20: SUPRIATI
A21: 900000188076906 | B21: 26068390389 | C21: 3515186806040006 | D21: YUNITA KUSUMAWATI | E21: SIDOARJO | F21: 28-06-2004 | N21: YUNITAKUSUMAWATI057@GMAIL.COM | O21: 62881027544049 | P21: T | Q21: RT 0/ RW 0 2011 18 3515 KODE POS | R21: S | T21: 0 | U21: T | V21: 01-05-2026 | W21: 31-12-3000 | X21: NUR LAILIYAH | AC21: NUR LAILIYAH
A22: 900000188076907 | B22: 26068390397 | C22: 3515184209050002 | D22: CITA ALFI RAHMADINI | E22: SIDOARJO | F22: 02-09-2005 | N22: CITAALFIRA2005@GMAIL.COM | O22: 628816365683 | P22: T | Q22: RT 0/ RW 0 2011 18 3515 KODE POS 61256 | R22: S | T22: 0 | U22: T | V22: 01-05-2026 | W22: 31-12-3000 | X22: UMUL LAILA | AC22: UMUL LAILA
A23: 900000188076912 | B23: 26068390447 | C23: 3515181501820004 | D23: PANDHU NARWATAMA | E23: SURAKARTA | F23: 15-01-1982 | N23: PANDHUNARWATAMA@GMAIL.COM | O23: 6281331026307 | P23: T | Q23: RT 0/ RW 0 2011 18 3515 KODE POS | R23: S | T23: 0 | U23: T | V23: 01-05-2026 | W23: 31-12-3000 | X23: PINARTI | AC23: PINARTI
A24: 900000188076918 | B24: 26068391155 | C24: 3515182212870006 | D24: AHMAD FAUZAN | E24: PASURUAN | F24: 22-12-1987 | N24: SABILABARKAHFAUZAN@GMAIL.COM | O24: 6282244412130 | P24: T | Q24: RT 0/ RW 0 2011 18 3515 KODE POS | R24: S | T24: 0 | U24: T | V24: 01-05-2026 | W24: 31-12-3000 | X24: KHUSNA | AC24: KHUSNA
A25: 900000188076927 | B25: 26068390009 | C25: 3515180702610001 | D25: DRS.USMAN HIDAYAT, M.PD | E25: BANGKALAN | F25: 07-02-1961 | N25: USMANHIDAYAT007@GMAIL.COM | O25: 62818587090 | P25: T | Q25: RT 0/ RW 0 2011 18 3515 KODE POS 61256 | R25: S | T25: 0 | U25: T | V25: 01-05-2026 | W25: 31-12-3000 | X25: AMINATUS. S | AC25: AMINATUS. S
A26: 900000188076937 | B26: 26068390207 | C26: 3515182611040001 | D26: I. KOMANG THIYO SINDHU ARTADANA | E26: SIDOARJO | F26: 26-11-2004 | N26: SINDHUARTADANA@GMAIL.COM | O26: 6285142293300 | P26: T | Q26: RT 0/ RW 0 2011 18 3515 KODE POS 0 | R26: S | T26: 0 | U26: T | V26: 01-05-2026 | W26: 31-12-3000 | X26: IDA AYU WAYAN RENTET | AC26: IDA AYU WAYAN RENTET
A27: 900000188076952 | B27: 26068389878 | C27: 3515182107040001 | D27: FIRLY RIFALDI ANANDA PRAJOGO | E27: SIDOARJO | F27: 21-07-2004 | N27: FIRLYRIFALDI@GMAIL.COM | O27: 6287858154443 | P27: T | Q27: RT 0/ RW 0 2011 18 3515 KODE POS 0 | R27: S | T27: 0 | U27: T | V27: 01-05-2026 | W27: 31-12-3000 | X27: MASRIATUN | AC27: MASRIATUN
A28: 900000188076954 | B28: 26068389845 | C28: 3515183107790002 | D28: ERIK TRIASMORO | E28: SURABAYA | F28: 31-07-1979 | N28: AYUNG.SUNNI2@GMAIL.COM | O28: 628882378717 | P28: T | Q28: RT 0/ RW 0 2011 18 3515 KODE POS 61256 | R28: S | T28: 0 | U28: T | V28: 01-05-2026 | W28: 31-12-3000 | X28: SUHARNINGSIH | AC28: SUHARNINGSIH
A29: 900000188076957 | B29: 26068389860 | C29: 3515182511800002 | D29: DEDIK NOVIANTO | E29: SIDOARJO | F29: 25-11-1980 | N29: HARTINYNOV2@GMAIL.COM | O29: 6282229974251 | P29: T | Q29: RT 0/ RW 0 2011 18 3515 KODE POS | R29: S | T29: 0 | U29: T | V29: 01-05-2026 | W29: 31-12-3000 | X29: DJUNTIK MUSRIPAH | AC29: DJUNTIK MUSRIPAH
A30: 900000188076959 | B30: 26068389894 | C30: 3515182406720006 | D30: MOCH SOLEH | E30: SURABAYA | F30: 24-06-1972 | N30: DIMASILHAM91463@GMAIL.COM | O30: 6281337847660 | P30: T | Q30: RT 0/ RW 0 2011 18 3515 KODE POS | R30: S | T30: 0 | U30: T | V30: 01-05-2026 | W30: 31-12-3000 | X30: MARIYAM | AC30: MARIYAM
... A43: 900000188602367 | B43: 26068389688 | C43: 3515180312940003 | D43: MUHAMMAD HAFIDZ | E43: SURABAYA | F43: 03-12-1994 | N43: MUHAMMADHAFIDZ26NU@GMAIL.COM | O43: 6283803980526 | P43: T | Q43: RT 0/ RW 0 2011 18 3515 KODE POS 61256 | R43: S | T43: 0 | U43: T | V43: 01-05-2026 | W43: 31-12-3000 | X43: HJ.SHOLIKHAH | AC43: HJ.SHOLIKHAH

Sheet Sheet2
A1: KODE_PEMBINA | B1: NAMA_PEMBINA | C1: KODE_TK | D1: KPJ | E1: KODE_SEGMEN | F1: NPP | G1: NAMA_PEMBINA | H1: NOMOR_IDENTITAS | I1: STATUS_INVALID_IDENTITAS | J1: NAMA_LENGKAP | K1: TGL_LAHIR | L1: NAMA_IBU_KANDUNG | M1: HANDPHONE | N1: EMAIL | O1: NIK_QUALITY | P1: NAMA_QUALITY | Q1: TGL_LAHIR_QUALITY | R1: IBU_QUALITY | S1: HP_QUALITY | T1: EMAIL_QUALITY | U1: TK_AKTIF | V1: TK_BARU | W1: KATEGORI | X1: POTENSI_IBU | Y1: POTENSI_HP | Z1: P_MSG
A2: FE282550 | B2: FELY PRISMAWATI | C2: 900000018335562 | D2: 19046726816 | E2: PU | F2: 15061864 | G2: FELY PRISMAWATI | H2: 3578062508750008 | I2: 0 | J2: MUJIONO | K2: 27631 | L2: MAMI | M2: 6282231073306 | N2: MONO89250@GMAIL.COM | O2: GOOD | P2: GOOD | Q2: GOOD | R2: INACURATE | S2: GOOD | T2: GOOD | U2: 1 | V2: 0 | W2: KUALITAS_TK_AKTIF | Z2: Null
A3: FE282550 | B3: FELY PRISMAWATI | C3: 900000106928719 | D3: 23132247117 | E3: PU | F3: 16010397 | G3: FELY PRISMAWATI | H3: 5371011008780002 | I3: 0 | J3: AGUSTINUS ROBERT ABIA PULEK | K3: 28712 | L3: DORT JE H. PULEK-LOGO | M3: 6282145734516 | N3: ROJRPULEK@GMAIL.COM | O3: GOOD | P3: GOOD | Q3: GOOD | R3: INCOMPLETE | S3: GOOD | T3: GOOD | U3: 1 | V3: 0 | W3: KUALITAS_TK_AKTIF | X3: DORTJE H. PULEK-LOGO | Z3: Null
A4: AD278940 | B4: ADINDA SEPTHIARIYAN | C4: 170302011451334 | D4: 17010182800 | E4: PU | F4: 16019135 | G4: ADINDA SEPTHIARIYAN | H4: E80692008 | I4: 0 | J4: ZHAI HONGGUANG | K4: 23439 | M4: 6281552330603 | N4: KUNSHENGINTERNATIONAL@YAHOO.COM | O4: GOOD | P4: GOOD | Q4: GOOD | R4: INACURATE | S4: GOOD | T4: GOOD | U4: 1 | V4: 0 | W4: KUALITAS_TK_AKTIF | Z4: Null
A5: AM255040 | B5: AMALIA PRAHASTUTI | C5: 900000188022372 | D5: 26065012937 | E5: PU | F5: 16050284 | G5: AMALIA PRAHASTUTI | H5: 3578040907630004 | I5: 0 | J5: BOEDI MOELJONO KOESHARTONO, DRS | K5: 23201 | L5: LIEM GIOK JAN NIO | M5: 6289680373540 | O5: GOOD | P5: GOOD | Q5: GOOD | R5: INCOMPLETE | S5: GOOD | T5: INCOMPLETE | U5: 1 | V5: 1 | W5: KUALITAS_TK_AKTIF | Z5: Null
A6: FE282550 | B6: FELY PRISMAWATI | C6: 170130010383617 | D6: 17003147364 | E6: PU | F6: 17008232 | G6: FELY PRISMAWATI | H6: 9271012105700007 | I6: 0 | J6: LUTFI | K6: 25709 | L6: - | M6: 87855643644 | N6: LUTF978@GMAIL.COM | O6: GOOD | P6: GOOD | Q6: GOOD | R6: INCOMPLETE | S6: GOOD | T6: INACURATE | U6: 1 | V6: 0 | W6: KUALITAS_TK_AKTIF | Z6: Null
A7: SE183690 | B7: SETIAWAN SAPUTRA | C7: 170523013971214 | D7: 17022385342 | E7: PU | F7: 17053147 | G7: SETIAWAN SAPUTRA | H7: E60868692 | I7: 0 | J7: WANG HAILIANG | K7: 30576 | M7: 6282358754150 | N7: WANGHAILIANG@GMAIL.COM | O7: GOOD | P7: GOOD | Q7: GOOD | R7: INACURATE | S7: GOOD | T7: GOOD | U7: 1 | V7: 0 | W7: KUALITAS_TK_AKTIF | Z7: Null
A8: SE183690 | B8: SETIAWAN SAPUTRA | C8: 170608014361714 | D8: 17024847398 | E8: PU | F8: 17059657 | G8: SETIAWAN SAPUTRA | H8: KJ0147723 | I8: 0 | J8: KO SIU CHIT | K8: 29509 | M8: 6281282065888 | O8: GOOD | P8: GOOD | Q8: GOOD | R8: INACURATE | S8: GOOD | T8: INCOMPLETE | U8: 1 | V8: 0 | W8: KUALITAS_TK_AKTIF | Z8: Null
A9: AM255040 | B9: AMALIA PRAHASTUTI | C9: 170714015069566 | D9: 17030548329 | E9: PU | F9: 17071243 | G9: AMALIA PRAHASTUTI | H9: E07435090 | I9: 0 | J9: CAI YONG KANG | K9: 25166 | M9: 6281161116508 | N9: CAI.YONG420@GMAIL.COM | O9: GOOD | P9: GOOD | Q9: GOOD | R9: INACURATE | S9: GOOD | T9: GOOD | U9: 1 | V9: 0 | W9: KUALITAS_TK_AKTIF | Z9: Null
A10: AM255040 | B10: AMALIA PRAHASTUTI | C10: 170714015069569 | D10: 17030548352 | E10: PU | F10: 17071243 | G10: AMALIA PRAHASTUTI | H10: EC8267115 | I10: 0 | J10: OPSIMAR GINA GONZALES | K10: 31018 | M10: 628162118787 | N10: GINA.GONZALES@GMAIL.COM | O10: GOOD | P10: GOOD | Q10: GOOD | R10: INACURATE | S10: GOOD | T10: GOOD | U10: 1 | V10: 0 | W10: KUALITAS_TK_AKTIF | Z10: Null
A11: RE166590 | B11: RENDY JULIAN TRISNA | C11: 900000190171563 | D11: 26080740850 | E11: PU | F11: 18029069 | G11: RENDY JULIAN TRISNA | H11: 5371022112970006 | I11: 0 | J11: RIVAN SAMUEL NGGEBU | K11: 35785 | L11: MARICE SOFIA NGGEBU | M11: 62812361016 | N11: RIVAN.SAMUEL.NGGEBU97@GMAIL.COM | O11: GOOD | P11: GOOD | Q11: GOOD | R11: INCOMPLETE | S11: GOOD | T11: GOOD | U11: 1 | V11: 1 | W11: KUALITAS_TK_AKTIF | X11: MARICE SOFIA NGGEBU | Z11: Null
A12: AM255040 | B12: AMALIA PRAHASTUTI | C12: 900000006251086 | D12: 18054453198 | E12: PU | F12: 18164547 | G12: AMALIA PRAHASTUTI | H12: E41532313 | I12: 0 | J12: MA YONGCHEN | K12: 28863 | M12: 6281924793698 | N12: MAYONGCHEN@GMAIL.COM | O12: GOOD | P12: GOOD | Q12: GOOD | R12: INACURATE | S12: GOOD | T12: GOOD | U12: 1 | V12: 0 | W12: KUALITAS_TK_AKTIF | Z12: Null
A13: FE282550 | B13: FELY PRISMAWATI | C13: 900000007890956 | D13: 18069630459 | E13: PU | F13: 18231573 | G13: FELY PRISMAWATI | H13: E09611292 | I13: 0 | J13: WANG YONGGUANG | K13: 25142 | M13: 628158765430 | N13: YONGGUANG31@GMAIL.COM | O13: GOOD | P13: GOOD | Q13: GOOD | R13: INACURATE | S13: GOOD | T13: GOOD | U13: 1 | V13: 0 | W13: KUALITAS_TK_AKTIF | Z13: Null
A14: FE282550 | B14: FELY PRISMAWATI | C14: 900000007890752 | D14: 18069630467 | E14: PU | F14: 18231573 | G14: FELY PRISMAWATI | H14: E59648150 | I14: 0 | J14: DING DIANHUI | K14: 21423 | M14: 81621133623 | N14: DIANHUI26@GMAIL.COM | O14: GOOD | P14: GOOD | Q14: GOOD | R14: INACURATE | S14: GOOD | T14: GOOD | U14: 1 | V14: 0 | W14: KUALITAS_TK_AKTIF | Z14: Null
A15: FE282550 | B15: FELY PRISMAWATI | C15: 900000182350289 | D15: 26047317206 | E15: PU | F15: 18246402 | G15: FELY PRISMAWATI | H15: 3329161512990005 | I15: 0 | J15: ARYANTO WIHATMOJO | K15: 36144 | L15: HENI TUSYANTI | M15: 6285799483846 | N15: AWMARLIQUE@GMAIL.COM | O15: GOOD | P15: GOOD | Q15: GOOD | R15: INACURATE | S15: GOOD | T15: GOOD | U15: 1 | V15: 1 | W15: KUALITAS_TK_AKTIF | Z15: Null
A16: AM255040 | B16: AMALIA PRAHASTUTI | C16: 900000013798767 | D16: 19004885943 | E16: PU | F16: 19020038 | G16: AMALIA PRAHASTUTI | H16: 3515174709740001 | I16: 0 | J16: PENNY SRI RAHAYU | K16: 27279 | L16: - | M16: 628123074431 | N16: PENNY_CPM@YAHOO.COM | O16: GOOD | P16: GOOD | Q16: GOOD | R16: INCOMPLETE | S16: GOOD | T16: GOOD | U16: 1 | V16: 0 | W16: KUALITAS_TK_AKTIF | Z16: Null
A17: RE166590 | B17: RENDY JULIAN TRISNA | C17: 900000186574873 | D17: 26054724575 | E17: PU | F17: 19150483 | G17: RENDY JULIAN TRISNA | H17: 3513071609960002 | I17: 0 | J17: SURIYANTO | K17: 35324 | L17: ERNAWATI | M17: 62895320587601 | N17: SURIYANTO99@GMAIL.COM | O17: GOOD | P17: GOOD | Q17: GOOD | R17: INCOMPLETE | S17: GOOD | T17: INUNIQUENESS | U17: 1 | V17: 1 | W17: KUALITAS_TK_AKTIF | Z17: Null
A18: RE166590 | B18: RENDY JULIAN TRISNA | C18: 900000186574787 | D18: 26054722918 | E18: PU | F18: 19150483 | G18: RENDY JULIAN TRISNA | H18: 3507191910970005 | I18: 0 | J18: BAGAS ARIYA DI PANGGA | K18: 35722 | L18: NUNUK HERAWATI | M18: 6289613473495 | O18: GOOD | P18: GOOD | Q18: GOOD | R18: INCOMPLETE | S18: GOOD | T18: INCOMPLETE | U18: 1 | V18: 1 | W18: KUALITAS_TK_AKTIF | Z18: Null
A19: RE166590 | B19: RENDY JULIAN TRISNA | C19: 900000186574860 | D19: 26054724187 | E19: PU | F19: 19150483 | G19: RENDY JULIAN TRISNA | H19: 3507096901890003 | I19: 0 | J19: SHINTA DEWI KUSWANDARI | K19: 32537 | L19: TITIK KUSRINI | M19: 6281216747366 | N19: SHINTADEWIKUSWANDARI18@GMAIL.COM | O19: GOOD | P19: GOOD | Q19: GOOD | R19: INCOMPLETE | S19: GOOD | T19: GOOD | U19: 1 | V19: 1 | W19: KUALITAS_TK_AKTIF | Z19: Null
A20: RE166590 | B20: RENDY JULIAN TRISNA | C20: 900000186574791 | D20: 26054723023 | E20: PU | F20: 19150483 | G20: RENDY JULIAN TRISNA | H20: 3578032812900003 | I20: 0 | J20: DAUD ABSHAR AFIFAINUDDIN | K20: 33235 | L20: MINUK INDAH PUDJIARIATI | M20: 6283135368804 | O20: GOOD | P20: GOOD | Q20: GOOD | R20: INCOMPLETE | S20: GOOD | T20: INCOMPLETE | U20: 1 | V20: 1 | W20: KUALITAS_TK_AKTIF | Z20: Null
A21: RE166590 | B21: RENDY JULIAN TRISNA | C21: 900000036783450 | D21: 21005395815 | E21: PU | F21: 19150483 | G21: RENDY JULIAN TRISNA | H21: 3577026302830002 | I21: 0 | J21: PURNAWATI | K21: 30370 | L21: MUJIATI | M21: 6281335003883 | N21: PURNAANA74@GMAIL.COM | O21: GOOD | P21: GOOD | Q21: GOOD | R21: INCOMPLETE | S21: GOOD | T21: GOOD | U21: 1 | V21: 0 | W21: KUALITAS_TK_AKTIF | X21: MUJIATI | Z21: Null
A22: RE166590 | B22: RENDY JULIAN TRISNA | C22: 900000186574876 | D22: 26054724591 | E22: PU | F22: 19150483 | G22: RENDY JULIAN TRISNA | H22: 3508046006720002 | I22: 0 | J22: SURYATI | K22: 26470 | L22: SRIANI | M22: 6285853289706 | O22: GOOD | P22: GOOD | Q22: GOOD | R22: INCOMPLETE | S22: GOOD | T22: INCOMPLETE | U22: 1 | V22: 1 | W22: KUALITAS_TK_AKTIF | Z22: Null
A23: RE166590 | B23: RENDY JULIAN TRISNA | C23: 900000186574878 | D23: 26054724617 | E23: PU | F23: 19150483 | G23: RENDY JULIAN TRISNA | H23: 3508044109890001 | I23: 0 | J23: TITIN WEKE MUSTIKA WAHYUNI | K23: 32752 | L23: SUKRISTIN MEGAWATI | M23: 6285785255026 | N23: TITINWEKEMUSTIKAWAHYUNI98@GMAIL.COM | O23: GOOD | P23: GOOD | Q23: GOOD | R23: INCOMPLETE | S23: GOOD | T23: GOOD | U23: 1 | V23: 1 | W23: KUALITAS_TK_AKTIF | Z23: Null
A24: RE166590 | B24: RENDY JULIAN TRISNA | C24: 900000186574866 | D24: 26054724252 | E24: PU | F24: 19150483 | G24: RENDY JULIAN TRISNA | H24: 3517056504960001 | I24: 0 | J24: SRI LUPI TIRANTI | K24: 35180 | L24: SUSMIATI | M24: 6281316902196 | N24: SRILUPITIRANTI49@GMAIL.COM | O24: GOOD | P24: GOOD | Q24: GOOD | R24: INCOMPLETE | S24: GOOD | T24: GOOD | U24: 1 | V24: 1 | W24: KUALITAS_TK_AKTIF | Z24: Null
A25: RE166590 | B25: RENDY JULIAN TRISNA | C25: 900000186574794 | D25: 26054723049 | E25: PU | F25: 19150483 | G25: RENDY JULIAN TRISNA | H25: 3508046609690001 | I25: 0 | J25: DWI ENI SUPRAPTI | K25: 25472 | L25: NIFIN | M25: 6281232779772 | O25: GOOD | P25: GOOD | Q25: GOOD | R25: INCOMPLETE | S25: GOOD | T25: INCOMPLETE | U25: 1 | V25: 1 | W25: KUALITAS_TK_AKTIF | Z25: Null
A26: RE166590 | B26: RENDY JULIAN TRISNA | C26: 900000186574807 | D26: 26054723254 | E26: PU | F26: 19150483 | G26: RENDY JULIAN TRISNA | H26: 3504035506890001 | I26: 0 | J26: FITROTUL LATHIFAH | K26: 32674 | L26: MINGGIROTIN | M26: 6285236865354 | N26: FITROTULLATHIFAH68@GMAIL.COM | O26: GOOD | P26: GOOD | Q26: GOOD | R26: INCOMPLETE | S26: GOOD | T26: GOOD | U26: 1 | V26: 1 | W26: KUALITAS_TK_AKTIF | Z26: Null
A27: RE166590 | B27: RENDY JULIAN TRISNA | C27: 900000186574838 | D27: 26054724518 | E27: PU | F27: 19150483 | G27: RENDY JULIAN TRISNA | H27: 3514125211830002 | I27: 0 | J27: NANIK PRIMADONA | K27: 30632 | L27: ESTER NILAWATI | M27: 628123533524 | O27: GOOD | P27: GOOD | Q27: GOOD | R27: INCOMPLETE | S27: GOOD | T27: INCOMPLETE | U27: 1 | V27: 1 | W27: KUALITAS_TK_AKTIF | Z27: Null
A28: RE166590 | B28: RENDY JULIAN TRISNA | C28: 900000186574788 | D28: 26054722942 | E28: PU | F28: 19150483 | G28: RENDY JULIAN TRISNA | H28: 3524090705890003 | I28: 0 | J28: BETRI ABDUL ROHMAN | K28: 32635 | L28: SUWARTI | M28: 6287872315932 | O28: GOOD | P28: GOOD | Q28: GOOD | R28: INCOMPLETE | S28: GOOD | T28: INCOMPLETE | U28: 1 | V28: 1 | W28: KUALITAS_TK_AKTIF | Z28: Null
A29: RE166590 | B29: RENDY JULIAN TRISNA | C29: 900000186574796 | D29: 26054723072 | E29: PU | F29: 19150483 | G29: RENDY JULIAN TRISNA | H29: 3518141406650003 | I29: 0 | J29: EDY DARIJANTO | K29: 23907 | L29: SUPARMI | M29: 6285235542328 | O29: GOOD | P29: GOOD | Q29: GOOD | R29: INCOMPLETE | S29: GOOD | T29: INCOMPLETE | U29: 1 | V29: 1 | W29: KUALITAS_TK_AKTIF | Z29: Null
A30: RE166590 | B30: RENDY JULIAN TRISNA | C30: 900000186574789 | D30: 26054722967 | E30: PU | F30: 19150483 | G30: RENDY JULIAN TRISNA | H30: 3577032908880001 | I30: 0 | J30: BIMA PRIMAGA YUDHA | K30: 32384 | L30: SURTI SUKANTI | M30: 6282233353085 | O30: GOOD | P30: GOOD | Q30: GOOD | R30: INCOMPLETE | S30: GOOD | T30: INCOMPLETE | U30: 1 | V30: 1 | W30: KUALITAS_TK_AKTIF | Z30: Null
A31: RE166590 | B31: RENDY JULIAN TRISNA | C31: 900000186574816 | D31: 26054724310 | E31: PU | F31: 19150483 | G31: RENDY JULIAN TRISNA | H31: 3510207011770006 | I31: 0 | J31: ISTIANAH MARDIA | K31: 28459 | L31: SUTIYAH | M31: 6282145157378 | O31: GOOD | P31: GOOD | Q31: GOOD | R31: INCOMPLETE | S31: GOOD | T31: INCOMPLETE | U31: 1 | V31: 1 | W31: KUALITAS_TK_AKTIF | Z31: Null
A32: RE166590 | B32: RENDY JULIAN TRISNA | C32: 900000186574852 | D32: 26054724120 | E32: PU | F32: 19150483 | G32: RENDY JULIAN TRISNA | H32: 3513043010990001 | I32: 0 | J32: RIZQI WIDIYANTO | K32: 36463 | L32: TUTIK HERIYATI | M32: 6281232746921 | O32: GOOD | P32: GOOD | Q32: GOOD | R32: INCOMPLETE | S32: GOOD | T32: INCOMPLETE | U32: 1 | V32: 1 | W32: KUALITAS_TK_AKTIF | Z32: Null
A33: RE166590 | B33: RENDY JULIAN TRISNA | C33: 900000186574858 | D33: 26054724179 | E33: PU | F33: 19150483 | G33: RENDY JULIAN TRISNA | H33: 3502191809830001 | I33: 0 | J33: SARTONO | K33: 30577 | L33: SARMINI | M33: 6281230174399 | O33: GOOD | P33: GOOD | Q33: GOOD | R33: INCOMPLETE | S33: GOOD | T33: INCOMPLETE | U33: 1 | V33: 1 | W33: KUALITAS_TK_AKTIF | Z33: Null
A34: RE166590 | B34: RENDY JULIAN TRISNA | C34: 900000186574778 | D34: 26054722694 | E34: PU | F34: 19150483 | G34: RENDY JULIAN TRISNA | H34: 3509212608950001 | I34: 0 | J34: ANDRIANUS RICHO TAKAHINDANGEN | K34: 34937 | L34: YOVIA AGUSTINA | M34: 6285704291702 | N34: RIKORELAWAN24@GMAIL.COM | O34: GOOD | P34: GOOD | Q34: GOOD | R34: INCOMPLETE | S34: GOOD | T34: GOOD | U34: 1 | V34: 1 | W34: KUALITAS_TK_AKTIF | Z34: Null
A35: TU263440 | B35: TUMIAR ROHANA SIMANJUNTAK | C35: 900000192915449 | D35: 26099611340 | E35: PU | F35: 19346578 | G35: TUMIAR ROHANA SIMANJUNTAK | H35: 3515040104070001 | I35: 0 | J35: ABYANSYAH DA'VAREL | K35: 39173 | L35: SUHARTATIK | M35: 6289515661561 | N35: ABIYANSYAHDAFAREL@GMAIL.COM | O35: GOOD | P35: GOOD | Q35: GOOD | R35: INACURATE | S35: GOOD | T35: GOOD | U35: 1 | V35: 1 | W35: KUALITAS_TK_AKTIF | X35: SUHARTATIK | Z35: Null
A36: TU263440 | B36: TUMIAR ROHANA SIMANJUNTAK | C36: 900000184086901 | D36: 26045784845 | E36: PU | F36: 19346578 | G36: TUMIAR ROHANA SIMANJUNTAK | H36: 3514121501950004 | I36: 0 | J36: TEGUH | K36: 34714 | L36: NIKMAWATI | M36: 62895601068800 | N36: TEGUH19@GMAIL.COM | O36: GOOD | P36: GOOD | Q36: GOOD | R36: INACURATE | S36: GOOD | T36: INUNIQUENESS | U36: 1 | V36: 1 | W36: KUALITAS_TK_AKTIF | Z36: Null
A37: YU274390 | B37: YURISCA PUTRI MAHARDINI | C37: 900000194102258 | D37: 26101026784 | E37: PU | F37: 20014468 | G37: YURISCA PUTRI MAHARDINI | H37: 3515135512020001 | I37: 0 | J37: SUROTUL HUMIROH | K37: 37575 | L37: SITI NUR HASANAH | M37: 6281932125140 | N37: HUMIROHSUROTUL@GMAIL.COM | O37: GOOD | P37: GOOD | Q37: GOOD | R37: INACURATE | S37: GOOD | T37: GOOD | U37: 1 | V37: 1 | W37: KUALITAS_TK_AKTIF | X37: SITI NUR HASANAH | Z37: Null
A38: IR138520 | B38: IRSAN SIGMA OCTAVIAN | C38: 160126001461508 | D38: 16006634758 | E38: PU | F38: 20023498 | G38: IRSAN SIGMA OCTAVIAN | H38: 6471013112760046 | I38: 0 | J38: ALIAS.M | K38: 28125 | L38: AISYAH | M38: 6289517979034 | N38: ATOMUSTAFA76@GMAIL.COM | O38: GOOD | P38: GOOD | Q38: GOOD | R38: INCOMPLETE | S38: GOOD | T38: GOOD | U38: 1 | V38: 0 | W38: KUALITAS_TK_AKTIF | X38: AISYAH | Z38: Null
A39: IR138520 | B39: IRSAN SIGMA OCTAVIAN | C39: 171627181 | D39: 15049659491 | E39: PU | F39: 20023498 | G39: IRSAN SIGMA OCTAVIAN | H39: 6471020604830002 | I39: 0 | J39: SUPRAPTO | K39: 30412 | L39: MARLIYAH | M39: 6285246526658 | N39: PRAPTO.ATHENA@GMAIL.COM | O39: GOOD | P39: GOOD | Q39: GOOD | R39: INCOMPLETE | S39: GOOD | T39: GOOD | U39: 1 | V39: 0 | W39: KUALITAS_TK_AKTIF | X39: MARLIYAH | Z39: Null
A40: IR138520 | B40: IRSAN SIGMA OCTAVIAN | C40: 900000042453302 | D40: 21033506037 | E40: PU | F40: 20023498 | G40: IRSAN SIGMA OCTAVIAN | H40: 6.471052e+15 | I40: 0 | J40: SAMSURI JUHARI | K40: 27534 | L40: NORSAM | M40: 6285654147926 | N40: SAMSURIJUHARI89@GMAIL.COM | O40: GOOD | P40: GOOD | Q40: GOOD | R40: INCOMPLETE | S40: GOOD | T40: GOOD | U40: 1 | V40: 0 | W40: KUALITAS_TK_AKTIF | X40: NORSAM | Z40: Null
...
